[2024-08-15T02:23:06.634+0000] {taskinstance.py:1159} INFO - Dependencies all met for dep_context=non-requeueable deps ti=<TaskInstance: fetch_weather_data.fetch_weather_data scheduled__2024-08-14T00:00:00+00:00 [queued]>
[2024-08-15T02:23:06.647+0000] {taskinstance.py:1159} INFO - Dependencies all met for dep_context=requeueable deps ti=<TaskInstance: fetch_weather_data.fetch_weather_data scheduled__2024-08-14T00:00:00+00:00 [queued]>
[2024-08-15T02:23:06.647+0000] {taskinstance.py:1361} INFO - Starting attempt 1 of 2
[2024-08-15T02:23:06.669+0000] {taskinstance.py:1382} INFO - Executing <Task(SimpleHttpOperator): fetch_weather_data> on 2024-08-14 00:00:00+00:00
[2024-08-15T02:23:06.676+0000] {standard_task_runner.py:57} INFO - Started process 79 to run task
[2024-08-15T02:23:06.680+0000] {standard_task_runner.py:84} INFO - Running: ['***', 'tasks', 'run', 'fetch_weather_data', 'fetch_weather_data', 'scheduled__2024-08-14T00:00:00+00:00', '--job-id', '15', '--raw', '--subdir', 'DAGS_FOLDER/call_api.py', '--cfg-path', '/tmp/tmpte4hsvlw']
[2024-08-15T02:23:06.684+0000] {standard_task_runner.py:85} INFO - Job 15: Subtask fetch_weather_data
[2024-08-15T02:23:06.750+0000] {task_command.py:416} INFO - Running <TaskInstance: fetch_weather_data.fetch_weather_data scheduled__2024-08-14T00:00:00+00:00 [running]> on host 7f78744f4816
[2024-08-15T02:23:06.877+0000] {taskinstance.py:1662} INFO - Exporting env vars: AIRFLOW_CTX_DAG_OWNER='***' AIRFLOW_CTX_DAG_ID='fetch_weather_data' AIRFLOW_CTX_TASK_ID='fetch_weather_data' AIRFLOW_CTX_EXECUTION_DATE='2024-08-14T00:00:00+00:00' AIRFLOW_CTX_TRY_NUMBER='1' AIRFLOW_CTX_DAG_RUN_ID='scheduled__2024-08-14T00:00:00+00:00'
[2024-08-15T02:23:06.880+0000] {http.py:143} INFO - Calling HTTP method
[2024-08-15T02:23:06.907+0000] {taskinstance.py:1937} ERROR - Task failed with exception
Traceback (most recent call last):
  File "/home/airflow/.local/lib/python3.8/site-packages/airflow/providers/http/operators/http.py", line 145, in execute
    response = http.run(self.endpoint, self.data, self.headers, self.extra_options)
  File "/home/airflow/.local/lib/python3.8/site-packages/airflow/providers/http/hooks/http.py", line 145, in run
    session = self.get_conn(headers)
  File "/home/airflow/.local/lib/python3.8/site-packages/airflow/providers/http/hooks/http.py", line 98, in get_conn
    conn = self.get_connection(self.http_conn_id)
  File "/home/airflow/.local/lib/python3.8/site-packages/airflow/hooks/base.py", line 72, in get_connection
    conn = Connection.get_connection_from_secrets(conn_id)
  File "/home/airflow/.local/lib/python3.8/site-packages/airflow/models/connection.py", line 477, in get_connection_from_secrets
    raise AirflowNotFoundException(f"The conn_id `{conn_id}` isn't defined")
airflow.exceptions.AirflowNotFoundException: The conn_id `my_http_connection` isn't defined
[2024-08-15T02:23:06.913+0000] {taskinstance.py:1400} INFO - Marking task as UP_FOR_RETRY. dag_id=fetch_weather_data, task_id=fetch_weather_data, execution_date=20240814T000000, start_date=20240815T022306, end_date=20240815T022306
[2024-08-15T02:23:06.934+0000] {standard_task_runner.py:104} ERROR - Failed to execute job 15 for task fetch_weather_data (The conn_id `my_http_connection` isn't defined; 79)
[2024-08-15T02:23:06.973+0000] {local_task_job_runner.py:228} INFO - Task exited with return code 1
[2024-08-15T02:23:06.994+0000] {taskinstance.py:2778} INFO - 0 downstream tasks scheduled from follow-on schedule check
