[2024-08-04T09:55:45.892+0000] {taskinstance.py:1159} INFO - Dependencies all met for dep_context=non-requeueable deps ti=<TaskInstance: excel_to_oracle_dag.load_excel_to_oracle manual__2024-08-04T09:50:41.363505+00:00 [queued]>
[2024-08-04T09:55:45.899+0000] {taskinstance.py:1159} INFO - Dependencies all met for dep_context=requeueable deps ti=<TaskInstance: excel_to_oracle_dag.load_excel_to_oracle manual__2024-08-04T09:50:41.363505+00:00 [queued]>
[2024-08-04T09:55:45.899+0000] {taskinstance.py:1361} INFO - Starting attempt 2 of 2
[2024-08-04T09:55:45.911+0000] {taskinstance.py:1382} INFO - Executing <Task(PythonOperator): load_excel_to_oracle> on 2024-08-04 09:50:41.363505+00:00
[2024-08-04T09:55:45.917+0000] {standard_task_runner.py:57} INFO - Started process 311 to run task
[2024-08-04T09:55:45.920+0000] {standard_task_runner.py:84} INFO - Running: ['***', 'tasks', 'run', 'excel_to_oracle_dag', 'load_excel_to_oracle', 'manual__2024-08-04T09:50:41.363505+00:00', '--job-id', '10', '--raw', '--subdir', 'DAGS_FOLDER/excel_to_oracle_dag.py', '--cfg-path', '/tmp/tmpjmbjmk7v']
[2024-08-04T09:55:45.921+0000] {standard_task_runner.py:85} INFO - Job 10: Subtask load_excel_to_oracle
[2024-08-04T09:55:45.965+0000] {task_command.py:416} INFO - Running <TaskInstance: excel_to_oracle_dag.load_excel_to_oracle manual__2024-08-04T09:50:41.363505+00:00 [running]> on host b230a9a3e87a
[2024-08-04T09:55:46.033+0000] {taskinstance.py:1662} INFO - Exporting env vars: AIRFLOW_CTX_DAG_OWNER='***' AIRFLOW_CTX_DAG_ID='excel_to_oracle_dag' AIRFLOW_CTX_TASK_ID='load_excel_to_oracle' AIRFLOW_CTX_EXECUTION_DATE='2024-08-04T09:50:41.363505+00:00' AIRFLOW_CTX_TRY_NUMBER='2' AIRFLOW_CTX_DAG_RUN_ID='manual__2024-08-04T09:50:41.363505+00:00'
[2024-08-04T09:55:46.051+0000] {taskinstance.py:1937} ERROR - Task failed with exception
Traceback (most recent call last):
  File "/home/airflow/.local/lib/python3.8/site-packages/airflow/operators/python.py", line 192, in execute
    return_value = self.execute_callable()
  File "/home/airflow/.local/lib/python3.8/site-packages/airflow/operators/python.py", line 209, in execute_callable
    return self.python_callable(*self.op_args, **self.op_kwargs)
  File "/opt/airflow/dags/excel_to_oracle_dag.py", line 38, in load_excel_to_oracle
    conn = BaseHook.get_connection(conn_id)
  File "/home/airflow/.local/lib/python3.8/site-packages/airflow/hooks/base.py", line 72, in get_connection
    conn = Connection.get_connection_from_secrets(conn_id)
  File "/home/airflow/.local/lib/python3.8/site-packages/airflow/models/connection.py", line 477, in get_connection_from_secrets
    raise AirflowNotFoundException(f"The conn_id `{conn_id}` isn't defined")
airflow.exceptions.AirflowNotFoundException: The conn_id `Connection bai test` isn't defined
[2024-08-04T09:55:46.057+0000] {taskinstance.py:1400} INFO - Marking task as FAILED. dag_id=excel_to_oracle_dag, task_id=load_excel_to_oracle, execution_date=20240804T095041, start_date=20240804T095545, end_date=20240804T095546
[2024-08-04T09:55:46.069+0000] {standard_task_runner.py:104} ERROR - Failed to execute job 10 for task load_excel_to_oracle (The conn_id `Connection bai test` isn't defined; 311)
[2024-08-04T09:55:46.092+0000] {local_task_job_runner.py:228} INFO - Task exited with return code 1
[2024-08-04T09:55:46.110+0000] {taskinstance.py:2778} INFO - 0 downstream tasks scheduled from follow-on schedule check
